[2021-10-31 17:40:49,649] {taskinstance.py:896} INFO - Dependencies all met for <TaskInstance: user_processing.creating_table 2021-10-30T00:00:00+00:00 [queued]>
[2021-10-31 17:40:49,672] {taskinstance.py:896} INFO - Dependencies all met for <TaskInstance: user_processing.creating_table 2021-10-30T00:00:00+00:00 [queued]>
[2021-10-31 17:40:49,673] {taskinstance.py:1087} INFO - 
--------------------------------------------------------------------------------
[2021-10-31 17:40:49,673] {taskinstance.py:1088} INFO - Starting attempt 1 of 1
[2021-10-31 17:40:49,673] {taskinstance.py:1089} INFO - 
--------------------------------------------------------------------------------
[2021-10-31 17:40:49,682] {taskinstance.py:1107} INFO - Executing <Task(PostgresOperator): creating_table> on 2021-10-30T00:00:00+00:00
[2021-10-31 17:40:49,690] {standard_task_runner.py:52} INFO - Started process 133237 to run task
[2021-10-31 17:40:49,694] {standard_task_runner.py:76} INFO - Running: ['***', 'tasks', 'run', 'user_processing', 'creating_table', '2021-10-30T00:00:00+00:00', '--job-id', '3', '--pool', 'default_pool', '--raw', '--subdir', 'DAGS_FOLDER/user_processing.py', '--cfg-path', '/tmp/tmpuzzd0r06', '--error-file', '/tmp/tmpppo9xra4']
[2021-10-31 17:40:49,695] {standard_task_runner.py:77} INFO - Job 3: Subtask creating_table
[2021-10-31 17:40:49,749] {logging_mixin.py:104} INFO - Running <TaskInstance: user_processing.creating_table 2021-10-30T00:00:00+00:00 [running]> on host 97c0b02b7dd2
[2021-10-31 17:40:49,809] {taskinstance.py:1302} INFO - Exporting the following env vars:
AIRFLOW_CTX_DAG_OWNER=***
AIRFLOW_CTX_DAG_ID=user_processing
AIRFLOW_CTX_TASK_ID=creating_table
AIRFLOW_CTX_EXECUTION_DATE=2021-10-30T00:00:00+00:00
AIRFLOW_CTX_DAG_RUN_ID=scheduled__2021-10-30T00:00:00+00:00
[2021-10-31 17:40:49,810] {postgres.py:68} INFO - Executing: 
            CREATE TABLE IF NOT EXISTS users (
                firstname TEXT NOT NULL,
                lastname TEXT NOT NULL,
                country TEXT NOT NULL,
                username TEXT NOT NULL,
                password TEXT NOT NULL,
                email TEXT NOT NULL PRIMARY KEY
            );
        
[2021-10-31 17:40:49,829] {taskinstance.py:1501} ERROR - Task failed with exception
Traceback (most recent call last):
  File "/home/airflow/.local/lib/python3.6/site-packages/airflow/models/taskinstance.py", line 1157, in _run_raw_task
    self._prepare_and_execute_task_with_callbacks(context, task)
  File "/home/airflow/.local/lib/python3.6/site-packages/airflow/models/taskinstance.py", line 1331, in _prepare_and_execute_task_with_callbacks
    result = self._execute_task(context, task_copy)
  File "/home/airflow/.local/lib/python3.6/site-packages/airflow/models/taskinstance.py", line 1361, in _execute_task
    result = task_copy.execute(context=context)
  File "/home/airflow/.local/lib/python3.6/site-packages/airflow/providers/postgres/operators/postgres.py", line 70, in execute
    self.hook.run(self.sql, self.autocommit, parameters=self.parameters)
  File "/home/airflow/.local/lib/python3.6/site-packages/airflow/hooks/dbapi.py", line 177, in run
    with closing(self.get_conn()) as conn:
  File "/home/airflow/.local/lib/python3.6/site-packages/airflow/providers/postgres/hooks/postgres.py", line 88, in get_conn
    conn = deepcopy(self.connection or self.get_connection(conn_id))
  File "/home/airflow/.local/lib/python3.6/site-packages/airflow/hooks/base.py", line 67, in get_connection
    conn = Connection.get_connection_from_secrets(conn_id)
  File "/home/airflow/.local/lib/python3.6/site-packages/airflow/models/connection.py", line 379, in get_connection_from_secrets
    raise AirflowNotFoundException(f"The conn_id `{conn_id}` isn't defined")
airflow.exceptions.AirflowNotFoundException: The conn_id `db_pg` isn't defined
[2021-10-31 17:40:49,831] {taskinstance.py:1551} INFO - Marking task as FAILED. dag_id=user_processing, task_id=creating_table, execution_date=20211030T000000, start_date=20211031T174049, end_date=20211031T174049
[2021-10-31 17:40:49,865] {local_task_job.py:149} INFO - Task exited with return code 1
